Workbook

Sheet Cover
B2: Unilever PLC
B3: Integrated 3-Statement & DCF Model
B4: EUR millions unless stated
B7: Version / date | C7: v1.1, built 30 October 2026. Market data: share price = delayed quote, late Oct 2026; 10-yr Bund yield = 21 Aug 2026.
B8: Prepared by | C8: Jhanvee Kamal Parikh
B9: Purpose | C9: Portfolio review and portfolio-of-work sample
B10: Active scenario | C10: =Assumptions!D4&" case (change in ASSUMPTIONS!C4: 1 = Worst, 2 = Base, 3 = Best)" -> Base case (change in ASSUMPTIONS!C4: 1 = Worst, 2 = Base, 3 = Best)
B12: CONTENTS
B13: Summary | C13: One-page executive summary: valuation, scenarios, financial summary, risks
B14: DATA_INPUT | C14: Historical FY23-FY25 statements (inputs) and FY26E-FY30E income statement and balance sheet
B15: ASSUMPTIONS | C15: All forecast drivers, scenario selector and Worst / Base / Best inputs
B16: CASH_FLOW | C16: Indirect cash flow statement, dividends, buybacks and net debt memo
B17: DCF | C17: WACC, free cash flow to firm, valuation bridge, sensitivity grid, scenario comparison
B19: HOW TO USE
C20: 1. Pick the case in ASSUMPTIONS!C4 (yellow cell). Everything flows through the three statements and the valuation.
C21: 2. Change inputs only in blue cells. Black cells are formulas and green cells link to other sheets.
C22: 3. Refresh the share price, Bund yield and beta on the DCF sheet before relying on the output.
C23: 4. Confirm both integrity checks below read OK after any change.
B25: COLOUR CODE
B26: Blue text | C26: Hard-coded input or assumption
B27: Black text | C27: Formula / calculation
B28: Green text | C28: Link to another sheet
B29: Yellow cell | C29: Scenario selector (ASSUMPTIONS!C4)
B31: MODEL INTEGRITY (live)
B32: Balance sheet | C32: =IF(SUMPRODUCT(ABS('Data Input'!C50:J50))<0.5,"OK - balance sheet balances in all years","CHECK - balance sheet does not balance") -> OK - balance sheet balances in all years
B33: Formula errors | C33: =IF(SUMPRODUCT(--ISERROR('Data Input'!A1:J60))+SUMPRODUCT(--ISERROR(Assumptions!A1:K70))+SUMPRODUCT(--ISERROR('Cash flow'!A1:J40))+SUMPRODUCT(--ISERROR(DCF!A1:J80))=0,"OK - no formula errors","CHECK - formula errors found") -> OK - no formula errors
B35: SOURCES
C36: Unilever Q4 and Full Year 2025 results announcement (12 Feb 2026): historical statements
C37: Unilever 2026 First Half Results (Jul 2026): current trading and outlook
C38: Euronext Amsterdam delayed quote (UNA.NV), 10-yr German Bund yield, TradingView beta: market inputs
B40: Illustrative analysis only; not investment advice.

Sheet Summary
A1: Unilever PLC - Executive Summary
A2: ="Active scenario: "&Assumptions!D4&" | EUR millions unless stated | Valuation date 31-Dec-2025 balance sheet" -> Active scenario: Base | EUR millions unless stated | Valuation date 31-Dec-2025 balance sheet
A5: ="Headline: "&Assumptions!D4&" case implies EUR "&TEXT(DCF!C55,"0.00")&" per share vs EUR "&TEXT(DCF!C7,"0.00")&" current price ("&TEXT(DCF!C57,"+0%;-0%")&")." -> Headline: Base case implies EUR 67.93 per share vs EUR 53.90 current price (+26%).
A6: ="Scenario range (static snapshot): EUR "&TEXT(DCF!C77,"0")&" (Worst) to EUR "&TEXT(DCF!E77,"0")&" (Best); Base EUR "&TEXT(DCF!D77,"0")&". Terminal value is "&TEXT(DCF!C46,"0%")&" of enterprise value." -> Scenario range (static snapshot): EUR 51 (Worst) to EUR 80 (Best); Base EUR 68. Terminal value is 81% of enterprise value.
A8: VALUATION SNAPSHOT (live, active scenario)
A9: Enterprise value | C9: =DCF!C45 -> 171662.33
A10: Equity value | C10: =DCF!C53 -> 148044.33
A11: Implied value per share (EUR) | C11: =DCF!C55 -> 67.925824
A12: Current share price (EUR) | C12: =DCF!C7 -> 53.9
A13: Upside / (downside) | C13: =DCF!C57 -> 0.26021936
A14: WACC | C14: =DCF!C19 -> 0.066682938
A15: Terminal growth | C15: =DCF!C20 -> 0.02
A16: Implied terminal EV / EBITDA | C16: =DCF!C47 -> 14.225422
A17: Current market EV / FY25 EBITDA | C17: =DCF!C58 -> 13.636131
A19: SCENARIO COMPARISON (static snapshot from DCF sheet)
C20: Worst | D20: Base | E20: Best | G20: Chart data
A21: FY30E turnover | C21: =DCF!C72 -> 54670.091 | D21: =DCF!D72 -> 59392.362 | E21: =DCF!E72 -> 62921.38 | G21: Worst | H21: =DCF!C77 -> 50.709662
A22: FY30E EBIT margin | C22: =DCF!C73 -> 0.175 | D22: =DCF!D73 -> 0.194 | E22: =DCF!E73 -> 0.205 | G22: Base | H22: =DCF!D77 -> 67.925824
A23: FY30E FCFF | C23: =DCF!C74 -> 6570.1926 | D23: =DCF!D74 -> 8507.0004 | E23: =DCF!E74 -> 9874.8364 | G23: Best | H23: =DCF!E77 -> 80.126489
A24: Enterprise value | C24: =DCF!C75 -> 134139.71 | D24: =DCF!D75 -> 171662.33 | E24: =DCF!E75 -> 198253.68 | G24: Price | H24: =DCF!C7 -> 53.9
A25: Implied value per share (EUR) | C25: =DCF!C77 -> 50.709662 | D25: =DCF!D77 -> 67.925824 | E25: =DCF!E77 -> 80.126489
A26: Upside / (downside) | C26: =DCF!C78 -> -0.059189945 | D26: =DCF!D78 -> 0.26021936 | E26: =DCF!E78 -> 0.48657679
A28: FINANCIAL SUMMARY (live, active scenario) | C28: FY23 | D28: FY24 | E28: FY25 | F28: FY26E | G28: FY27E | H28: FY28E | I28: FY29E | J28: FY30E
A29: Turnover | C29: ='Data Input'!C6 -> 51680 | D29: ='Data Input'!D6 -> 52479 | E29: ='Data Input'!E6 -> 50503 | F29: ='Data Input'!F6 -> 51260.545 | G29: ='Data Input'!G6 -> 53054.664 | H29: ='Data Input'!H6 -> 55176.851 | I29: ='Data Input'!I6 -> 57383.925 | J29: ='Data Input'!J6 -> 59392.362
A30: growth | C30: - | D30: ='Data Input'!D15 -> 0.015460526 | E30: ='Data Input'!E15 -> -0.037653157 | F30: ='Data Input'!F15 -> 0.015 | G30: ='Data Input'!G15 -> 0.035 | H30: ='Data Input'!H15 -> 0.04 | I30: ='Data Input'!I15 -> 0.04 | J30: ='Data Input'!J15 -> 0.035
A31: EBIT (operating profit) | C31: ='Data Input'!C7 -> 8998 | D31: ='Data Input'!D7 -> 8829 | E31: ='Data Input'!E7 -> 9037 | F31: ='Data Input'!F7 -> 9431.9403 | G31: ='Data Input'!G7 -> 9921.2222 | H31: ='Data Input'!H7 -> 10483.602 | I31: ='Data Input'!I7 -> 11017.714 | J31: ='Data Input'!J7 -> 11522.118
A32: EBIT margin | C32: ='Data Input'!C16 -> 0.17410991 | D32: ='Data Input'!D16 -> 0.16823872 | E32: ='Data Input'!E16 -> 0.17893986 | F32: ='Data Input'!F16 -> 0.184 | G32: ='Data Input'!G16 -> 0.187 | H32: ='Data Input'!H16 -> 0.19 | I32: ='Data Input'!I16 -> 0.192 | J32: ='Data Input'!J16 -> 0.194
A33: Net profit (continuing) | C33: ='Data Input'!C12 -> 6636 | D33: ='Data Input'!D12 -> 6039 | E33: ='Data Input'!E12 -> 6212 | F33: ='Data Input'!F12 -> 6602.9962 | G33: ='Data Input'!G12 -> 7003.4214 | H33: ='Data Input'!H12 -> 7465.6333 | I33: ='Data Input'!I12 -> 7861.2321 | J33: ='Data Input'!J12 -> 8236.0387
A34: Free cash flow to firm | F34: =DCF!F34 -> 6755.2468 | G34: =DCF!G34 -> 7274.7979 | H34: =DCF!H34 -> 7779.0871 | I34: =DCF!I34 -> 8175.1788 | J34: =DCF!J34 -> 8507.0004
A35: Net debt / EBITDA (x) | E35: ='Cash flow'!E36 -> 2.3520827 | F35: ='Cash flow'!F36 -> 2.2887636 | G35: ='Cash flow'!G36 -> 2.1897336 | H35: ='Cash flow'!H36 -> 2.0742516 | I35: ='Cash flow'!I36 -> 1.9678183 | J35: ='Cash flow'!J36 -> 1.873386
A36: FY23-FY25 are reported; FY26E-FY30E are projections. Net debt = financial liabilities less cash.
A38: KEY ASSUMPTIONS (active scenario)
A39: ="Revenue growth: "&TEXT(Assumptions!F6,"0.0%")&" in FY26E, "&TEXT(Assumptions!J6,"0.0%")&" by FY30E" -> Revenue growth: 1.5% in FY26E, 3.5% by FY30E
A40: ="Reported EBIT margin: "&TEXT('Data Input'!E16,"0.0%")&" (FY25) to "&TEXT(Assumptions!J7,"0.0%")&" (FY30E)" -> Reported EBIT margin: 17.9% (FY25) to 19.4% (FY30E)
A41: ="Effective tax rate: "&TEXT(Assumptions!F10,"0.0%")&" falling/settling at "&TEXT(Assumptions!J10,"0.0%") -> Effective tax rate: 27.0% falling/settling at 26.0%
A42: ="Capital returns: "&TEXT(Assumptions!F18,"0%")&" dividend payout plus EUR "&TEXT(Assumptions!F19,"#,##0")&"m annual buybacks; gross debt held flat" -> Capital returns: 78% dividend payout plus EUR 1,500m annual buybacks; gross debt held flat
A43: ="Discounting: WACC "&TEXT(DCF!C19,"0.0%")&" (beta "&TEXT(DCF!C11,"0.00")&"), terminal growth "&TEXT(DCF!C20,"0.0%") -> Discounting: WACC 6.7% (beta 0.80), terminal growth 2.0%
A45: KEY RISKS AND CAVEATS
A46: - Valuation is dominated by terminal value and is highly sensitive to WACC (see DCF sensitivity grid).
A47: - FY23 and FY24 balance sheets include Ice Cream while the income statement excludes it; forecasts are anchored on FY25 only.
...

Sheet Data Input
A1: UNILEVER PLC
A2: Integrated 3-Statement Financial Model
A3: Currency: EUR (€) in Millions
A5: CONSOLIDATED INCOME STATEMENT | B5: Units | C5: FY23 | D5: FY24 | E5: FY25 | F5: FY26E | G5: FY27E | H5: FY28E | I5: FY29E | J5: FY30E
A6: Turnover (Revenue) | B6: € Millions | C6: 51680 | D6: 52479 | E6: 50503 | F6: =E6*(1+Assumptions!F6) -> 51260.545 | G6: =F6*(1+Assumptions!G6) -> 53054.664 | H6: =G6*(1+Assumptions!H6) -> 55176.851 | I6: =H6*(1+Assumptions!I6) -> 57383.925 | J6: =I6*(1+Assumptions!J6) -> 59392.362
A7: Operating Profit (EBIT) | B7: € Millions | C7: 8998 | D7: 8829 | E7: 9037 | F7: =F6*Assumptions!F7 -> 9431.9403 | G7: =G6*Assumptions!G7 -> 9921.2222 | H7: =H6*Assumptions!H7 -> 10483.602 | I7: =I6*Assumptions!I7 -> 11017.714 | J7: =J6*Assumptions!J7 -> 11522.118
A8: Net Finance Cost | B8: € Millions | C8: -409 | D8: -520 | E8: -503 | F8: =-Assumptions!F8*(E37+E40-E31) -> -486.74 | G8: =-Assumptions!G8*(F37+F40-F31) -> -492.75773 | H8: =-Assumptions!H8*(G37+G40-G31) -> -494.90796 | I8: =-Assumptions!I8*(H37+H40-H31) -> -494.42689 | J8: =-Assumptions!J8*(I37+I40-I31) -> -492.33615
A9: Other Non-Operating Items (NET) | B9: € Millions | C9: 37 | D9: 62 | E9: 159 | F9: =Assumptions!F9 -> 100 | G9: =Assumptions!G9 -> 100 | H9: =Assumptions!H9 -> 100 | I9: =Assumptions!I9 -> 100 | J9: =Assumptions!J9 -> 100
A10: Profit Before Taxation | B10: € Millions | C10: =C7+C8+C9 -> 8626 | D10: =D7+D8+D9 -> 8371 | E10: =E7+E8+E9 -> 8693 | F10: =F7+F8+F9 -> 9045.2003 | G10: =G7+G8+G9 -> 9528.4645 | H10: =H7+H8+H9 -> 10088.694 | I10: =I7+I8+I9 -> 10623.287 | J10: =J7+J8+J9 -> 11129.782
A11: Taxation | B11: € Millions | C11: -1990 | D11: -2332 | E11: -2481 | F11: =-Assumptions!F10*F10 -> -2442.2041 | G11: =-Assumptions!G10*G10 -> -2525.0431 | H11: =-Assumptions!H10*H10 -> -2623.0604 | I11: =-Assumptions!I10*I10 -> -2762.0545 | J11: =-Assumptions!J10*J10 -> -2893.7433
A12: Net Profit from Continuing Operations | B12: € Millions | C12: =C10+C11 -> 6636 | D12: =D10+D11 -> 6039 | E12: =E10+E11 -> 6212 | F12: =F10+F11 -> 6602.9962 | G12: =G10+G11 -> 7003.4214 | H12: =H10+H11 -> 7465.6333 | I12: =I10+I11 -> 7861.2321 | J12: =J10+J11 -> 8236.0387
A14: Historical Ratio Analysis
A15: Revenue Growth Rate | B15: % | C15: - | D15: =(D6-C6)/C6 -> 0.015460526 | E15: =(E6-D6)/D6 -> -0.037653157 | F15: =(F6-E6)/E6 -> 0.015 | G15: =(G6-F6)/F6 -> 0.035 | H15: =(H6-G6)/G6 -> 0.04 | I15: =(I6-H6)/H6 -> 0.04 | J15: =(J6-I6)/I6 -> 0.035
A16: Operating Profit Margin | B16: % | C16: =C7/C6 -> 0.17410991 | D16: =D7/D6 -> 0.16823872 | E16: =E7/E6 -> 0.17893986 | F16: =F7/F6 -> 0.184 | G16: =G7/G6 -> 0.187 | H16: =H7/H6 -> 0.19 | I16: =I7/I6 -> 0.192 | J16: =J7/J6 -> 0.194
A17: Effective Tax Rate | B17: % | C17: =ABS(C11)/C10 -> 0.23069789 | D17: =ABS(D11)/D10 -> 0.27858081 | E17: =ABS(E11)/E10 -> 0.28540205 | F17: =ABS(F11)/F10 -> 0.27 | G17: =ABS(G11)/G10 -> 0.265 | H17: =ABS(H11)/H10 -> 0.26 | I17: =ABS(I11)/I10 -> 0.26 | J17: =ABS(J11)/J10 -> 0.26
A22: CONSOLIDATED BALANCE SHEET | B22: Units | C22: FY23 | D22: FY24 | E22: FY25 | F22: FY26E | G22: FY27E | H22: FY28E | I22: FY29E | J22: FY30E
A23: Non-Current Assets
A24: PP&E | B24: € Millions | C24: 10707 | D24: 11669 | E24: 8992 | F24: =E24-'Cash flow'!F16-'Cash flow'!F8 -> 9361.0759 | G24: =F24-'Cash flow'!G16-'Cash flow'!G8 -> 9743.0695 | H24: =G24-'Cash flow'!H16-'Cash flow'!H8 -> 10140.343 | I24: =H24-'Cash flow'!I16-'Cash flow'!I8 -> 10553.507 | J24: =I24-'Cash flow'!J16-'Cash flow'!J8 -> 10981.132
A25: Goodwill & Intangibles | B25: € Millions | C25: =21109+18357 -> 39466 | D25: =22311+18590 -> 40901 | E25: =SUM(17709,17055) -> 34764 | F25: =E25-'Cash flow'!F17-'Cash flow'!F9 -> 34676.857 | G25: =F25-'Cash flow'!G17-'Cash flow'!G9 -> 34586.664 | H25: =G25-'Cash flow'!H17-'Cash flow'!H9 -> 34492.863 | I25: =H25-'Cash flow'!I17-'Cash flow'!I9 -> 34395.311 | J25: =I25-'Cash flow'!J17-'Cash flow'!J9 -> 34294.344
A26: Other Non-Current Assets | B26: € Millions | C26: =SUM(1113,1386,911,3781) -> 7191 | D26: =SUM(4164,1280,1571,971) -> 7986 | E26: =SUM(4462,1146,3065,976) -> 9649 | F26: =E26*(1+Assumptions!F28) -> 9649 | G26: =F26*(1+Assumptions!G28) -> 9649 | H26: =G26*(1+Assumptions!H28) -> 9649 | I26: =H26*(1+Assumptions!I28) -> 9649 | J26: =I26*(1+Assumptions!J28) -> 9649
A27: Total Non-Current Assets | B27: € Millions | C27: =SUM(C24:C26) -> 57364 | D27: =SUM(D24:D26) -> 60556 | E27: =SUM(E24:E26) -> 53405 | F27: =SUM(F24:F26) -> 53686.933 | G27: =SUM(G24:G26) -> 53978.734 | H27: =SUM(H24:H26) -> 54282.206 | I27: =SUM(I24:I26) -> 54597.818 | J27: =SUM(J24:J26) -> 54924.476
A28: Current Asset
A29: Inventories | B29: € Millions | C29: 5119 | D29: 5177 | E29: 4043 | F29: =F6*Assumptions!F24 -> 4100.8436 | G29: =G6*Assumptions!G24 -> 4244.3731 | H29: =H6*Assumptions!H24 -> 4414.1481 | I29: =I6*Assumptions!I24 -> 4590.714 | J29: =J6*Assumptions!J24 -> 4751.389
A30: Trade & Other Receivables | B30: € Millions | C30: 5775 | D30: 6011 | E30: 7346 | F30: =F6*Assumptions!F25 -> 7432.779 | G30: =G6*Assumptions!G25 -> 7692.9263 | H30: =H6*Assumptions!H25 -> 8000.6433 | I30: =I6*Assumptions!I25 -> 8320.6691 | J30: =J6*Assumptions!J25 -> 8611.8925
A31: Cash & Cash Equivalents | B31: € Millions | C31: 4159 | D31: 6136 | E31: 3941 | F31: ='Cash flow'!F29 -> 3640.1135 | G31: ='Cash flow'!G29 -> 3532.6018 | H31: ='Cash flow'!H29 -> 3556.6557 | I31: ='Cash flow'!I29 -> 3661.1924 | J31: ='Cash flow'!J29 -> 3799.74
A32: Other Current Asset | B32: € Millions | C32: =SUM(427,1731,691) -> 2849 | D32: =SUM(373,1330,167) -> 1870 | E32: =SUM(329,1121,286) -> 1736 | F32: =E32*(1+Assumptions!F26) -> 1736 | G32: =F32*(1+Assumptions!G26) -> 1736 | H32: =G32*(1+Assumptions!H26) -> 1736 | I32: =H32*(1+Assumptions!I26) -> 1736 | J32: =I32*(1+Assumptions!J26) -> 1736
A33: Total Current Assets | B33: € Millions | C33: =SUM(C29:C32) -> 17902 | D33: =SUM(D29:D32) -> 19194 | E33: =SUM(E29:E32) -> 17066 | F33: =SUM(F29:F32) -> 16909.736 | G33: =SUM(G29:G32) -> 17205.901 | H33: =SUM(H29:H32) -> 17707.447 | I33: =SUM(I29:I32) -> 18308.575 | J33: =SUM(J29:J32) -> 18899.021
A34: Total Assets | B34: € Millions | C34: =SUM(C27,C33) -> 75266 | D34: =SUM(D27,D33) -> 79750 | E34: =SUM(E27,E33) -> 70471 | F34: =SUM(F27,F33) -> 70596.669 | G34: =SUM(G27,G33) -> 71184.635 | H34: =SUM(H27,H33) -> 71989.653 | I34: =SUM(I27,I33) -> 72906.393 | J34: =SUM(J27,J33) -> 73823.497
A35: Current Liabilities
A36: Trade Payables and Other Liabilities | B36: € Millions | C36: =SUM(16857,851, 537, 175) -> 18420 | D36: =SUM(16690,678,831,48) -> 18247 | E36: =SUM(16939,1439,589,113) -> 19080 | F36: =F6*Assumptions!F27 -> 19376.486 | G36: =G6*Assumptions!G27 -> 20054.663 | H36: =H6*Assumptions!H27 -> 20856.85 | I36: =I6*Assumptions!I27 -> 21691.124 | J36: =J6*Assumptions!J27 -> 22450.313
A37: Short-Term Financial Liabilities | B37: € Millions | C37: 5087 | D37: 6987 | E37: 2582 | F37: =E37 -> 2582 | G37: =F37 -> 2582 | H37: =G37 -> 2582 | I37: =H37 -> 2582 | J37: =I37 -> 2582
A38: Total Current Liability | B38: € Millions | C38: =SUM(C36:C37) -> 23507 | D38: =SUM(D36:D37) -> 25234 | E38: =SUM(E36:E37) -> 21662 | F38: =SUM(F36:F37) -> 21958.486 | G38: =SUM(G36:G37) -> 22636.663 | H38: =SUM(H36:H37) -> 23438.85 | I38: =SUM(I36:I37) -> 24273.124 | J38: =SUM(J36:J37) -> 25032.313
A39: Non-Current Liabilities
A40: Long-Term Financial Liabilities | B40: € Millions | C40: 24535 | D40: 25066 | E40: 25696 | F40: =E40+'Cash flow'!F21 -> 25696 | G40: =F40+'Cash flow'!G21 -> 25696 | H40: =G40+'Cash flow'!H21 -> 25696 | I40: =H40+'Cash flow'!I21 -> 25696 | J40: =I40+'Cash flow'!J21 -> 25696
A41: Other Non-Current Liabilities | B41: € Millions | C41: =SUM(384,351,1029,563,3995,138) -> 6460 | D41: =SUM(585,173,1021,571,4342,203) -> 6895 | E41: =SUM(303,100,844,539,3603,137) -> 5526 | F41: =E41*(1+Assumptions!F29) -> 5526 | G41: =F41*(1+Assumptions!G29) -> 5526 | H41: =G41*(1+Assumptions!H29) -> 5526 | I41: =H41*(1+Assumptions!I29) -> 5526 | J41: =I41*(1+Assumptions!J29) -> 5526
A42: Total Non-Current Liability | B42: € Millions | C42: =SUM(C40:C41) -> 30995 | D42: =SUM(D40:D41) -> 31961 | E42: =SUM(E40:E41) -> 31222 | F42: =SUM(F40:F41) -> 31222 | G42: =SUM(G40:G41) -> 31222 | H42: =SUM(H40:H41) -> 31222 | I42: =SUM(I40:I41) -> 31222 | J42: =SUM(J40:J41) -> 31222
A43: Total Liability | B43: € Millions | C43: =SUM(C38,C42) -> 54502 | D43: =SUM(D38,D42) -> 57195 | E43: =SUM(E38,E42) -> 52884 | F43: =SUM(F38,F42) -> 53180.486 | G43: =SUM(G38,G42) -> 53858.663 | H43: =SUM(H38,H42) -> 54660.85 | I43: =SUM(I38,I42) -> 55495.124 | J43: =SUM(J38,J42) -> 56254.313
A44: Shareholders' Equity
A45: Called-up Share Capital & Premium | B45: € Millions | C45: =(88+52844)-73364 -> -20432 | D45: =(88+52844)-73364 -> -20432 | E45: =(85+52844)-73364 -> -20435 | F45: =E45 -> -20435 | G45: =F45 -> -20435 | H45: =G45 -> -20435 | I45: =H45 -> -20435 | J45: =I45 -> -20435
A46: Retained Earnings | B46: € Millions | C46: =47052 - 8518 -> 38534 | D46: =49721-9299 -> 40422 | E46: =44229-8264 -> 35965 | F46: =E46+'Cash flow'!F33+'Cash flow'!F22+'Cash flow'!F23 -> 35794.183 | G46: =F46+'Cash flow'!G33+'Cash flow'!G22+'Cash flow'!G23 -> 35703.972 | H46: =G46+'Cash flow'!H33+'Cash flow'!H22+'Cash flow'!H23 -> 35706.804 | I46: =H46+'Cash flow'!I33+'Cash flow'!I22+'Cash flow'!I23 -> 35789.27 | J46: =I46+'Cash flow'!J33+'Cash flow'!J22+'Cash flow'!J23 -> 35947.184
...

Sheet Assumptions
A1: UNILEVER PLC
A2: Forecast Assumptions & Drivers (FY26E-FY30E)
A3: Currency: EUR (€) in Millions unless stated
A4: ACTIVE SCENARIO (1 = Worst, 2 = Base, 3 = Best) | C4: 2 | D4: =CHOOSE(C4,"Worst","Base","Best") -> Base
A5: INCOME STATEMENT DRIVERS | B5: Units | C5: FY23 | D5: FY24 | E5: FY25 | F5: FY26E | G5: FY27E | H5: FY28E | I5: FY29E | J5: FY30E | K5: Basis / source
A6: Revenue growth | B6: % | C6: - | D6: ='Data Input'!D15 -> 0.015460526 | E6: ='Data Input'!E15 -> -0.037653157 | F6: =CHOOSE($C$4,F35,F36,F37) -> 0.015 | G6: =CHOOSE($C$4,G35,G36,G37) -> 0.035 | H6: =CHOOSE($C$4,H35,H36,H37) -> 0.04 | I6: =CHOOSE($C$4,I35,I36,I37) -> 0.04 | J6: =CHOOSE($C$4,J35,J36,J37) -> 0.035 | K6: Scenario-driven: FY26E: H1-26 turnover +0.5% (USG 4.8%, FX -4.9%); FY guide USG 4-6% less FX/disposals. FY27E+: analyst view, below 4-6% multi-year USG guide after FX drag.
A7: Operating profit (EBIT) margin - reported | B7: % | C7: ='Data Input'!C16 -> 0.17410991 | D7: ='Data Input'!D16 -> 0.16823872 | E7: ='Data Input'!E16 -> 0.17893986 | F7: =CHOOSE($C$4,F40,F41,F42) -> 0.184 | G7: =CHOOSE($C$4,G40,G41,G42) -> 0.187 | H7: =CHOOSE($C$4,H40,H41,H42) -> 0.19 | I7: =CHOOSE($C$4,I40,I41,I42) -> 0.192 | J7: =CHOOSE($C$4,J40,J41,J42) -> 0.194 | K7: Scenario-driven: FY25 17.9% reported (20.0% underlying). H1-26 reported 19.1% (+40bps); guide: modest underlying improvement. Gradual drift as non-underlying costs fade.
A8: Net finance cost % of opening net financial debt | B8: % | C8: - | D8: =-'Data Input'!D8/('Data Input'!C37+'Data Input'!C40-'Data Input'!C31) -> 0.020421788 | E8: =-'Data Input'!E8/('Data Input'!D37+'Data Input'!D40-'Data Input'!D31) -> 0.019408111 | F8: 0.02 | G8: 0.02 | H8: 0.02 | I8: 0.02 | J8: 0.02 | K8: Calibrated to FY24-25 reported net finance cost (incl. pension income) over opening net financial liabilities. Opening balance used to avoid circularity.
A9: Other non-operating items (net) | B9: €m | C9: ='Data Input'!C9 -> 37 | D9: ='Data Input'!D9 -> 62 | E9: ='Data Input'!E9 -> 159 | F9: 100 | G9: 100 | H9: 100 | I9: 100 | J9: 100 | K9: JV/associate profit (~€245m FY25) less hyperinflation loss and other; FY23-25 range 37-159. Analyst estimate.
A10: Effective tax rate | B10: % | C10: ='Data Input'!C17 -> 0.23069789 | D10: ='Data Input'!D17 -> 0.27858081 | E10: ='Data Input'!E17 -> 0.28540205 | F10: =CHOOSE($C$4,F45,F46,F47) -> 0.27 | G10: =CHOOSE($C$4,G45,G46,G47) -> 0.265 | H10: =CHOOSE($C$4,H45,H46,H47) -> 0.26 | I10: =CHOOSE($C$4,I45,I46,I47) -> 0.26 | J10: =CHOOSE($C$4,J45,J46,J47) -> 0.26 | K10: Scenario-driven: Guidance: underlying ETR ~26%; reported ETR was 28.7% FY24 / 29.4% FY25 (disposal-related). Converges to 26%.
A11: NCI share of net profit | B11: % | D11: ='Cash flow'!D32/'Cash flow'!D6 -> 0.10084451 | E11: ='Cash flow'!E32/'Cash flow'!E6 -> 0.085479717 | F11: 0.085 | G11: 0.085 | H11: 0.085 | I11: 0.085 | J11: 0.085 | K11: FY25: NCI €531m on €6,213m continuing net profit (8.5%). Held flat.
A13: CASH FLOW & CAPITAL ALLOCATION DRIVERS | B13: Units | C13: FY23 | D13: FY24 | E13: FY25 | F13: FY26E | G13: FY27E | H13: FY28E | I13: FY29E | J13: FY30E | K13: Basis / source
A14: D&A % of turnover | B14: % | D14: ='Cash flow'!D7/'Data Input'!D6 -> 0.023552278 | E14: ='Cash flow'!E7/'Data Input'!E6 -> 0.025939053 | F14: 0.026 | G14: 0.026 | H14: 0.026 | I14: 0.026 | J14: 0.026 | K14: FY25 D&A €1,310m (2.6% of turnover), per UEBITDA reconciliation.
A15: Share of D&A relating to PP&E (rest = intangibles amortisation) | B15: % | F15: 0.8 | G15: 0.8 | H15: 0.8 | I15: 0.8 | J15: 0.8 | K15: ANALYST ESTIMATE - Unilever does not disclose the split in the results announcement. Affects PP&E vs intangibles balances only, not cash flow.
A16: Capex - PP&E % of turnover | B16: % | D16: =-'Cash flow'!D16/'Data Input'!D6 -> 0.026315288 | E16: =-'Cash flow'!E16/'Data Input'!E6 -> 0.028057739 | F16: =CHOOSE($C$4,F50,F51,F52) -> 0.028 | G16: =CHOOSE($C$4,G50,G51,G52) -> 0.028 | H16: =CHOOSE($C$4,H50,H51,H52) -> 0.028 | I16: =CHOOSE($C$4,I50,I51,I52) -> 0.028 | J16: =CHOOSE($C$4,J50,J51,J52) -> 0.028 | K16: Scenario-driven: FY25: €1,417m = 2.8% of turnover.
A17: Capex - intangibles % of turnover | B17: % | D17: =-'Cash flow'!D17/'Data Input'!D6 -> 0.0044398712 | E17: =-'Cash flow'!E17/'Data Input'!E6 -> 0.0034453399 | F17: 0.0035 | G17: 0.0035 | H17: 0.0035 | I17: 0.0035 | J17: 0.0035 | K17: FY25: €174m = 0.34% of turnover.
A18: Dividend payout (% of profit attributable to shareholders) | B18: % | D18: =-'Cash flow'!D22/'Cash flow'!D33 -> 0.79539595 | E18: =-'Cash flow'!E22/'Cash flow'!E33 -> 0.78384087 | F18: 0.78 | G18: 0.78 | H18: 0.78 | I18: 0.78 | J18: 0.78 | K18: FY25 cash dividends €4,453m / €5,682m = 78%.
A19: Share buybacks | B19: €m | D19: =-'Cash flow'!D23 -> 1508 | E19: =-'Cash flow'!E23 -> 1510 | F19: 1500 | G19: 1500 | H19: 1500 | I19: 1500 | J19: 1500 | K19: New €1.5bn programme announced Feb-26 (from Q2-26). FY27E+ assumes the same run-rate - analyst assumption.
A20: Dividends to NCI (% of NCI profit) | B20: % | D20: =-'Cash flow'!D24/'Cash flow'!D32 -> 1.1691297 | E20: =-'Cash flow'!E24/'Cash flow'!E32 -> 1.3709981 | F20: 1 | G20: 1 | H20: 1 | I20: 1 | J20: 1 | K20: FY25 €728m vs NCI profit €531m. Assumed 100% pay-out so NCI balance stays flat.
A21: Net debt issuance / (repayment) | B21: €m | F21: 0 | G21: 0 | H21: 0 | I21: 0 | J21: 0 | K21: Gross debt held flat (maturities refinanced). Positive = new borrowing (added to long-term financial liabilities); cash is the balancing item.
A23: BALANCE SHEET DRIVERS | B23: Units | C23: FY23 | D23: FY24 | E23: FY25 | F23: FY26E | G23: FY27E | H23: FY28E | I23: FY29E | J23: FY30E | K23: Basis / source
A24: Inventories % of turnover | B24: % | C24: n.m. | D24: n.m. | E24: ='Data Input'!E29/'Data Input'!E6 -> 0.08005465 | F24: =CHOOSE($C$4,F55,F56,F57) -> 0.08 | G24: =CHOOSE($C$4,G55,G56,G57) -> 0.08 | H24: =CHOOSE($C$4,H55,H56,H57) -> 0.08 | I24: =CHOOSE($C$4,I55,I56,I57) -> 0.08 | J24: =CHOOSE($C$4,J55,J56,J57) -> 0.08 | K24: Scenario-driven: FY25 only: FY23/FY24 balance sheets include Ice Cream while turnover excludes it, so earlier ratios are not comparable.
A25: Trade & other receivables % of turnover | B25: % | C25: n.m. | D25: n.m. | E25: ='Data Input'!E30/'Data Input'!E6 -> 0.14545671 | F25: =CHOOSE($C$4,F60,F61,F62) -> 0.145 | G25: =CHOOSE($C$4,G60,G61,G62) -> 0.145 | H25: =CHOOSE($C$4,H60,H61,H62) -> 0.145 | I25: =CHOOSE($C$4,I60,I61,I62) -> 0.145 | J25: =CHOOSE($C$4,J60,J61,J62) -> 0.145 | K25: Scenario-driven: FY25 includes TSA gross-up with The Magnum Ice Cream Co. (max 2 years) - receivables and payables both inflated; held at FY25 ratios so net effect is small.
A26: Other current assets - annual growth | B26: % | F26: 0 | G26: 0 | H26: 0 | I26: 0 | J26: 0 | K26: Held flat.
A27: Trade payables & other current liabilities % of turnover | B27: % | C27: n.m. | D27: n.m. | E27: ='Data Input'!E36/'Data Input'!E6 -> 0.37779934 | F27: 0.378 | G27: 0.378 | H27: 0.378 | I27: 0.378 | J27: 0.378 | K27: FY25: €19,080m (see TSA note above).
A28: Other non-current assets - annual growth | B28: % | F28: 0 | G28: 0 | H28: 0 | I28: 0 | J28: 0 | K28: Held flat (pension surplus, deferred tax, financial assets incl. retained TMICC stake).
A29: Other non-current liabilities - annual growth | B29: % | F29: 0 | G29: 0 | H29: 0 | I29: 0 | J29: 0 | K29: Held flat.
A31: Colour code: blue = hard-coded input / assumption, black = formula, green = link to another sheet. All forecast inputs are in columns F:J and can be overwritten.
A33: SCENARIO INPUTS (live rows above pick the case chosen in C4) | B33: Units | C33: FY23 | D33: FY24 | E33: FY25 | F33: FY26E | G33: FY27E | H33: FY28E | I33: FY29E | J33: FY30E | K33: Basis
A34: Revenue growth | K34: Worst: below guidance (FX drag persists, disposals). Base: as before. Best: mid-point of 4-6% USG guidance, FX neutral. Judgement, not consensus.
A35: Worst | B35: % | F35: 0.005 | G35: 0.015 | H35: 0.02 | I35: 0.02 | J35: 0.02
A36: Base | B36: % | F36: 0.015 | G36: 0.035 | H36: 0.04 | I36: 0.04 | J36: 0.035
A37: Best | B37: % | F37: 0.025 | G37: 0.05 | H37: 0.05 | I37: 0.05 | J37: 0.05
A39: EBIT margin (reported) | K39: Worst: no improvement on FY23-25 reported range. Base: gradual convergence. Best: reported margin approaches/exceeds underlying (20.0% FY25).
A40: Worst | B40: % | F40: 0.179 | G40: 0.177 | H40: 0.175 | I40: 0.175 | J40: 0.175
A41: Base | B41: % | F41: 0.184 | G41: 0.187 | H41: 0.19 | I41: 0.192 | J41: 0.194
A42: Best | B42: % | F42: 0.188 | G42: 0.194 | H42: 0.199 | I42: 0.203 | J42: 0.205
A44: Effective tax rate | K44: Worst: reported ETR stays near FY24-25 (28-29%). Best: underlying guidance of ~26% and slightly below.
A45: Worst | B45: % | F45: 0.28 | G45: 0.28 | H45: 0.275 | I45: 0.275 | J45: 0.275
A46: Base | B46: % | F46: 0.27 | G46: 0.265 | H46: 0.26 | I46: 0.26 | J46: 0.26
...

Sheet Cash flow
A1: UNILEVER PLC
A2: Cash Flow Statement (indirect) & Memo Items
A3: Currency: EUR (€) in Millions unless stated
A5: CASH FLOW STATEMENT | B5: Units | C5: FY23 | D5: FY24 | E5: FY25 | F5: FY26E | G5: FY27E | H5: FY28E | I5: FY29E | J5: FY30E
A6: Net profit from continuing operations | B6: €m | D6: ='Data Input'!D12 -> 6039 | E6: ='Data Input'!E12 -> 6212 | F6: ='Data Input'!F12 -> 6602.9962 | G6: ='Data Input'!G12 -> 7003.4214 | H6: ='Data Input'!H12 -> 7465.6333 | I6: ='Data Input'!I12 -> 7861.2321 | J6: ='Data Input'!J12 -> 8236.0387
A7: Depreciation & amortisation | B7: €m | D7: 1236 | E7: 1310 | F7: =Assumptions!F14*'Data Input'!F6 -> 1332.7742 | G7: =Assumptions!G14*'Data Input'!G6 -> 1379.4213 | H7: =Assumptions!H14*'Data Input'!H6 -> 1434.5981 | I7: =Assumptions!I14*'Data Input'!I6 -> 1491.982 | J7: =Assumptions!J14*'Data Input'!J6 -> 1544.2014
A8: o/w depreciation of PP&E | B8: €m | F8: =F7*Assumptions!F15 -> 1066.2193 | G8: =G7*Assumptions!G15 -> 1103.537 | H8: =H7*Assumptions!H15 -> 1147.6785 | I8: =I7*Assumptions!I15 -> 1193.5856 | J8: =J7*Assumptions!J15 -> 1235.3611
A9: o/w amortisation of goodwill & intangibles | B9: €m | F9: =F7-F8 -> 266.55483 | G9: =G7-G8 -> 275.88425 | H9: =H7-H8 -> 286.91962 | I9: =I7-I8 -> 298.39641 | J9: =J7-J8 -> 308.84028
A10: (Increase)/decrease in inventories | B10: €m | F10: =-('Data Input'!F29-'Data Input'!E29) -> -57.8436 | G10: =-('Data Input'!G29-'Data Input'!F29) -> -143.52953 | H10: =-('Data Input'!H29-'Data Input'!G29) -> -169.77493 | I10: =-('Data Input'!I29-'Data Input'!H29) -> -176.56592 | J10: =-('Data Input'!J29-'Data Input'!I29) -> -160.67499
A11: (Increase)/decrease in trade & other receivables | B11: €m | F11: =-('Data Input'!F30-'Data Input'!E30) -> -86.779025 | G11: =-('Data Input'!G30-'Data Input'!F30) -> -260.14727 | H11: =-('Data Input'!H30-'Data Input'!G30) -> -307.71705 | I11: =-('Data Input'!I30-'Data Input'!H30) -> -320.02573 | J11: =-('Data Input'!J30-'Data Input'!I30) -> -291.22342
A12: (Increase)/decrease in other current assets | B12: €m | F12: =-('Data Input'!F32-'Data Input'!E32) -> 0 | G12: =-('Data Input'!G32-'Data Input'!F32) -> 0 | H12: =-('Data Input'!H32-'Data Input'!G32) -> 0 | I12: =-('Data Input'!I32-'Data Input'!H32) -> 0 | J12: =-('Data Input'!J32-'Data Input'!I32) -> 0
A13: Increase/(decrease) in trade payables & other current liabilities | B13: €m | F13: ='Data Input'!F36-'Data Input'!E36 -> 296.48601 | G13: ='Data Input'!G36-'Data Input'!F36 -> 678.17701 | H13: ='Data Input'!H36-'Data Input'!G36 -> 802.18652 | I13: ='Data Input'!I36-'Data Input'!H36 -> 834.27398 | J13: ='Data Input'!J36-'Data Input'!I36 -> 759.18932
A14: Cash flow from operating activities | B14: €m | F14: =F6+F7+SUM(F10:F13) -> 8087.6338 | G14: =G6+G7+SUM(G10:G13) -> 8657.3429 | H14: =H6+H7+SUM(H10:H13) -> 9224.926 | I14: =I6+I7+SUM(I10:I13) -> 9690.8965 | J14: =J6+J7+SUM(J10:J13) -> 10087.531
A16: Capital expenditure - PP&E | B16: €m | D16: -1381 | E16: -1417 | F16: =-Assumptions!F16*'Data Input'!F6 -> -1435.2953 | G16: =-Assumptions!G16*'Data Input'!G6 -> -1485.5306 | H16: =-Assumptions!H16*'Data Input'!H6 -> -1544.9518 | I16: =-Assumptions!I16*'Data Input'!I6 -> -1606.7499 | J16: =-Assumptions!J16*'Data Input'!J6 -> -1662.9861
A17: Capital expenditure - intangibles | B17: €m | D17: -233 | E17: -174 | F17: =-Assumptions!F17*'Data Input'!F6 -> -179.41191 | G17: =-Assumptions!G17*'Data Input'!G6 -> -185.69132 | H17: =-Assumptions!H17*'Data Input'!H6 -> -193.11898 | I17: =-Assumptions!I17*'Data Input'!I6 -> -200.84374 | J17: =-Assumptions!J17*'Data Input'!J6 -> -207.87327
A18: Cash flow from investing activities | B18: €m | F18: =F16+F17 -> -1614.7072 | G18: =G16+G17 -> -1671.2219 | H18: =H16+H17 -> -1738.0708 | I18: =I16+I17 -> -1807.5936 | J18: =J16+J17 -> -1870.8594
A20: Financing activities | B20: €m
A21: Net debt issuance / (repayment) | B21: €m | F21: =Assumptions!F21 -> 0 | G21: =Assumptions!G21 -> 0 | H21: =Assumptions!H21 -> 0 | I21: =Assumptions!I21 -> 0 | J21: =Assumptions!J21 -> 0
A22: Dividends paid to shareholders | B22: €m | D22: -4319 | E22: -4453 | F22: =-Assumptions!F18*F33 -> -4712.5584 | G22: =-Assumptions!G18*G33 -> -4998.3418 | H22: =-Assumptions!H18*H33 -> -5328.2225 | I22: =-Assumptions!I18*I33 -> -5610.5614 | J22: =-Assumptions!J18*J33 -> -5878.0608
A23: Share buybacks | B23: €m | D23: -1508 | E23: -1510 | F23: =-Assumptions!F19 -> -1500 | G23: =-Assumptions!G19 -> -1500 | H23: =-Assumptions!H19 -> -1500 | I23: =-Assumptions!I19 -> -1500 | J23: =-Assumptions!J19 -> -1500
A24: Dividends paid to non-controlling interests | B24: €m | D24: -712 | E24: -728 | F24: =-Assumptions!F20*F32 -> -561.25468 | G24: =-Assumptions!G20*G32 -> -595.29082 | H24: =-Assumptions!H20*H32 -> -634.57883 | I24: =-Assumptions!I20*I32 -> -668.20473 | J24: =-Assumptions!J20*J32 -> -700.06329
A25: Cash flow from financing activities | B25: €m | F25: =SUM(F21:F24) -> -6773.8131 | G25: =SUM(G21:G24) -> -7093.6327 | H25: =SUM(H21:H24) -> -7462.8013 | I25: =SUM(I21:I24) -> -7778.7661 | J25: =SUM(J21:J24) -> -8078.1241
A27: Net change in cash | B27: €m | F27: =F14+F18+F25 -> -300.88648 | G27: =G14+G18+G25 -> -107.51171 | H27: =H14+H18+H25 -> 24.05385 | I27: =I14+I18+I25 -> 104.53677 | J27: =J14+J18+J25 -> 138.54752
A28: Opening cash & cash equivalents | B28: €m | F28: ='Data Input'!E31 -> 3941 | G28: ='Data Input'!F31 -> 3640.1135 | H28: ='Data Input'!G31 -> 3532.6018 | I28: ='Data Input'!H31 -> 3556.6557 | J28: ='Data Input'!I31 -> 3661.1924
A29: Closing cash & cash equivalents | B29: €m | F29: =F27+F28 -> 3640.1135 | G29: =G27+G28 -> 3532.6018 | H29: =H27+H28 -> 3556.6557 | I29: =I27+I28 -> 3661.1924 | J29: =J27+J28 -> 3799.74
A31: MEMO | B31: Units | C31: FY23 | D31: FY24 | E31: FY25 | F31: FY26E | G31: FY27E | H31: FY28E | I31: FY29E | J31: FY30E
A32: Net profit attributable to non-controlling interests | B32: €m | D32: 609 | E32: 531 | F32: =F6*Assumptions!F11 -> 561.25468 | G32: =G6*Assumptions!G11 -> 595.29082 | H32: =H6*Assumptions!H11 -> 634.57883 | I32: =I6*Assumptions!I11 -> 668.20473 | J32: =J6*Assumptions!J11 -> 700.06329
A33: Net profit attributable to shareholders | B33: €m | D33: =D6-D32 -> 5430 | E33: =E6-E32 -> 5681 | F33: =F6-F32 -> 6041.7415 | G33: =G6-G32 -> 6408.1306 | H33: =H6-H32 -> 6831.0545 | I33: =I6-I32 -> 7193.0274 | J33: =J6-J32 -> 7535.9754
A34: Free cash flow (operating + investing) | B34: €m | F34: =F14+F18 -> 6472.9266 | G34: =G14+G18 -> 6986.1209 | H34: =H14+H18 -> 7486.8552 | I34: =I14+I18 -> 7883.3029 | J34: =J14+J18 -> 8216.6717
A35: Closing net financial debt (financial liabilities less cash) | B35: €m | E35: ='Data Input'!E37+'Data Input'!E40-'Data Input'!E31 -> 24337 | F35: ='Data Input'!F37+'Data Input'!F40-'Data Input'!F31 -> 24637.886 | G35: ='Data Input'!G37+'Data Input'!G40-'Data Input'!G31 -> 24745.398 | H35: ='Data Input'!H37+'Data Input'!H40-'Data Input'!H31 -> 24721.344 | I35: ='Data Input'!I37+'Data Input'!I40-'Data Input'!I31 -> 24616.808 | J35: ='Data Input'!J37+'Data Input'!J40-'Data Input'!J31 -> 24478.26
A36: Net debt / EBITDA | B36: x | E36: =E35/('Data Input'!E7+E7) -> 2.3520827 | F36: =F35/('Data Input'!F7+F7) -> 2.2887636 | G36: =G35/('Data Input'!G7+G7) -> 2.1897336 | H36: =H35/('Data Input'!H7+H7) -> 2.0742516 | I36: =I35/('Data Input'!I7+I7) -> 1.9678183 | J36: =J35/('Data Input'!J7+J7) -> 1.873386
A38: FY24/FY25 columns hold reported figures (blue) for calibration only; forecast columns are formulas. Closing cash feeds DATA_INPUT row 31.
A39: Net debt here = financial liabilities less cash only (Unilever reports €23,076m at FY25 after also deducting other current financial assets and derivatives).

Sheet DCF
A1: UNILEVER PLC
A2: Discounted Cash Flow Valuation (FCFF)
A3: Currency: EUR (€) in Millions unless stated
A4: Active scenario: | C4: =Assumptions!D4 -> Base
A5: VALUATION INPUTS | C5: Input | D5: Source / note
A6: Valuation date (= balance sheet date) | C6: 46022 | D6: Cash flows are discounted to the FY25 balance sheet date, matching the net debt used in the bridge. Not rolled forward to today.
A7: Current share price (€) | C7: 53.9 | D7: Euronext Amsterdam (UNA.NV), delayed quote, retrieved late Oct-2026 - refresh before use.
A8: Shares outstanding (m) | C8: 2179.5 | D8: 31-Dec-2025, net of treasury shares (FY25 results, note 5). Excludes further buybacks.
A9: Risk-free rate | C9: 0.0325 | D9: German 10-yr Bund ~3.27% (21-Aug-2026); euro risk-free proxy - refresh before use.
A10: Equity risk premium | C10: 0.055 | D10: Analyst assumption (typical range 5-6%).
A11: Equity beta | C11: 0.8 | D11: Analyst assumption. Raw observed beta is only c.0.36 (TradingView); 0.80 is deliberately conservative so the implied terminal multiple (row 47) sits near the current market multiple (row 58). At 0.70 value is ~EUR 76/share.
A12: Cost of equity | C12: =C9+C11*C10 -> 0.0765 | D12: CAPM: Rf + beta x ERP
A13: Pre-tax cost of debt | C13: 0.035 | D13: 2025 issuance: 2.75%-3.5% fixed-rate euro notes (FY25 results, finance & liquidity).
A14: Tax rate (debt shield) | C14: =Assumptions!J10 -> 0.26 | D14: Terminal-year effective tax rate.
A15: After-tax cost of debt | C15: =C13*(1-C14) -> 0.0259
A16: Market capitalisation (€m) | C16: =C7*C8 -> 117475.05
A17: Gross financial liabilities (€m) | C17: ='Data Input'!E37+'Data Input'!E40 -> 28278 | D17: FY25 balance sheet: current + non-current financial liabilities (incl. leases).
A18: Debt weight D/(D+E) | C18: =C17/(C16+C17) -> 0.19401309 | D18: Market-value weights.
A19: WACC | C19: =C12*(1-C18)+C15*C18 -> 0.066682938
A20: Terminal growth rate | C20: 0.02 | D20: Analyst assumption ~ long-run euro-area inflation.
A21: Mid-year discounting (1 = on, 0 = off) | C21: 1 | D21: Terminal value is discounted with the same final-year factor as the last cash flow when mid-year is on.
A22: Other current financial assets (€m) | C22: 1121 | D22: FY25 balance sheet (note 8) - treasury investments, treated as cash-like. Included in Other Current Assets on DATA_INPUT.
A23: Retained 19.85% stake in TMICC at fair value (€m) | C23: 1655 | D23: FY25 results note 8(d): €1,655m. Non-operating asset; intended to be sold down.
A25: FREE CASH FLOW TO FIRM | B25: Units | C25: FY23 | D25: FY24 | E25: FY25 | F25: FY26E | G25: FY27E | H25: FY28E | I25: FY29E | J25: FY30E
A26: Turnover | B26: €m | C26: ='Data Input'!C6 -> 51680 | D26: ='Data Input'!D6 -> 52479 | E26: ='Data Input'!E6 -> 50503 | F26: ='Data Input'!F6 -> 51260.545 | G26: ='Data Input'!G6 -> 53054.664 | H26: ='Data Input'!H6 -> 55176.851 | I26: ='Data Input'!I6 -> 57383.925 | J26: ='Data Input'!J6 -> 59392.362
A27: EBITDA | B27: €m | D27: ='Data Input'!D7+'Cash flow'!D7 -> 10065 | E27: ='Data Input'!E7+'Cash flow'!E7 -> 10347 | F27: =F28+F31 -> 10764.714 | G27: =G28+G31 -> 11300.643 | H27: =H28+H31 -> 11918.2 | I27: =I28+I31 -> 12509.696 | J27: =J28+J31 -> 13066.32
A28: EBIT (operating profit) | B28: €m | C28: ='Data Input'!C7 -> 8998 | D28: ='Data Input'!D7 -> 8829 | E28: ='Data Input'!E7 -> 9037 | F28: ='Data Input'!F7 -> 9431.9403 | G28: ='Data Input'!G7 -> 9921.2222 | H28: ='Data Input'!H7 -> 10483.602 | I28: ='Data Input'!I7 -> 11017.714 | J28: ='Data Input'!J7 -> 11522.118
A29: Less: tax on EBIT | B29: €m | F29: =-F28*Assumptions!F10 -> -2546.6239 | G29: =-G28*Assumptions!G10 -> -2629.1239 | H29: =-H28*Assumptions!H10 -> -2725.7364 | I29: =-I28*Assumptions!I10 -> -2864.6055 | J29: =-J28*Assumptions!J10 -> -2995.7507
A30: NOPAT | B30: €m | F30: =F28+F29 -> 6885.3164 | G30: =G28+G29 -> 7292.0983 | H30: =H28+H29 -> 7757.8652 | I30: =I28+I29 -> 8153.108 | J30: =J28+J29 -> 8526.3675
A31: Plus: depreciation & amortisation | B31: €m | D31: ='Cash flow'!D7 -> 1236 | E31: ='Cash flow'!E7 -> 1310 | F31: ='Cash flow'!F7 -> 1332.7742 | G31: ='Cash flow'!G7 -> 1379.4213 | H31: ='Cash flow'!H7 -> 1434.5981 | I31: ='Cash flow'!I7 -> 1491.982 | J31: ='Cash flow'!J7 -> 1544.2014
A32: Less: capital expenditure | B32: €m | F32: ='Cash flow'!F16+'Cash flow'!F17 -> -1614.7072 | G32: ='Cash flow'!G16+'Cash flow'!G17 -> -1671.2219 | H32: ='Cash flow'!H16+'Cash flow'!H17 -> -1738.0708 | I32: ='Cash flow'!I16+'Cash flow'!I17 -> -1807.5936 | J32: ='Cash flow'!J16+'Cash flow'!J17 -> -1870.8594
A33: (Increase) / decrease in net working capital | B33: €m | F33: =SUM('Cash flow'!F10:F13) -> 151.86339 | G33: =SUM('Cash flow'!G10:G13) -> 274.50022 | H33: =SUM('Cash flow'!H10:H13) -> 324.69454 | I33: =SUM('Cash flow'!I10:I13) -> 337.68233 | J33: =SUM('Cash flow'!J10:J13) -> 307.29092
A34: Free cash flow to firm (FCFF) | B34: €m | F34: =F30+F31+F32+F33 -> 6755.2468 | G34: =G30+G31+G32+G33 -> 7274.7979 | H34: =H30+H31+H32+H33 -> 7779.0871 | I34: =I30+I31+I32+I33 -> 8175.1788 | J34: =J30+J31+J32+J33 -> 8507.0004
A35: FCFF growth | B35: % | G35: =G34/F34-1 -> 0.076910747 | H35: =H34/G34-1 -> 0.069320028 | I35: =I34/H34-1 -> 0.050917503 | J35: =J34/I34-1 -> 0.040588918
A36: Discount period (years) | B36: yrs | F36: =1-0.5*$C$21 -> 0.5 | G36: =F36+1 -> 1.5 | H36: =G36+1 -> 2.5 | I36: =H36+1 -> 3.5 | J36: =I36+1 -> 4.5
A37: Discount factor | B37: x | F37: =1/(1+$C$19)^F36 -> 0.96823845 | G37: =1/(1+$C$19)^G36 -> 0.9077097 | H37: =1/(1+$C$19)^H36 -> 0.85096487 | I37: =1/(1+$C$19)^I36 -> 0.79776739 | J37: =1/(1+$C$19)^J36 -> 0.74789552
A38: Present value of FCFF | B38: €m | F38: =F34*F37 -> 6540.6897 | G38: =G34*G37 -> 6603.4046 | H38: =H34*H37 -> 6619.7298 | I38: =I34*I37 -> 6521.891 | J38: =J34*J37 -> 6362.3475
A40: VALUATION
A41: Sum of PV of FCFF (FY26E-FY30E) | C41: =SUM(F38:J38) -> 32648.063
A42: Terminal-year FCFF (FY30E x (1+g)) | C42: =J34*(1+C20) -> 8677.1404
...
